<?xml version="1.0"?>
<robot name="tortoisebot-t2">
<!-- body of robot -->
 <link name="base_link">
    <visual>
      <geometry>
        <box size="0.6 0.3 0.3"/>
      </geometry>
      <material name="silver">
        <color rgba="0.75 0.75 0.75 1"/>
      </material>
    </visual>
    <collision>
      <geometry>
        <box size="0.6 0.3 0.3"/>
      </geometry>
    </collision>
    <inertial>
      <mass value="1.0"/>
      <inertia ixx="0.015" iyy="0.0375" izz="0.0375" ixy="0" ixz="0" iyz="0"/>
    </inertial>
  </link>

  <link name="front_caster">
    <visual>
      <geometry>
        <box size="0.1 0.1 0.3"/>
      </geometry>
      <material name="silver"/>
    </visual>
    <collision>
      <geometry>
        <box size="0.1 0.1 0.3"/>
      </geometry>
    </collision>
    <inertial>
      <mass value="0.1"/>
      <inertia ixx="0.00083" iyy="0.00083" izz="0.000167" ixy="0" ixz="0" iyz="0"/>
    </inertial>
  </link>

  <joint name="front_caster_joint" type="continuous">
    <axis xyz="0 0 1"/>
    <parent link="base_link"/>
    <child link="front_caster"/>
    <origin rpy="0 0 0" xyz="0.3 0 0"/>
  </joint>

  <link name="front_wheel">
    <visual>
      <geometry>
        <cylinder length="0.05" radius="0.035"/>
      </geometry>
       <material name="black">
          <color rgba="0 0 0 1"/>
      </material>
    </visual>
    <collision>
      <geometry>
        <cylinder length="0.05" radius="0.035"/>
      </geometry>
    </collision>
    <inertial>
      <mass value="0.1"/>
      <inertia ixx="5.1458e-5" iyy="5.1458e-5" izz="6.125e-5" ixy="0" ixz="0" iyz="0"/>
    </inertial>
  </link>

  <joint name="front_wheel_joint" type="continuous">
    <axis xyz="0 0 1"/>
    <parent link="front_caster"/>
    <child link="front_wheel"/>
    <origin rpy="-1.5708 0 0" xyz="0.05 0 -.15"/>
  </joint>

  <link name="right_wheel">
    <visual>
      <geometry>
        <cylinder length="0.05" radius="0.035"/>
      </geometry>
      <material name="black">
        <color rgba="0 0 0 1"/>
      </material>
    </visual>
    <collision>
      <geometry>
        <cylinder length="0.05" radius="0.035"/>
      </geometry>
    </collision>
    <inertial>
      <mass value="0.1"/>
      <inertia ixx="5.1458e-5" iyy="5.1458e-5" izz="6.125e-5" ixy="0" ixz="0" iyz="0"/>
    </inertial>
  </link>

  <joint name="right_wheel_joint" type="continuous">
    <axis xyz="0 0 1"/>
    <parent link="base_link"/>
    <child link="right_wheel"/>
    <origin rpy="-1.5708 0 0" xyz="-0.2825 -0.125 -.15"/>
  </joint>

  <link name="left_wheel">
    <visual>
      <geometry>
        <cylinder length="0.05" radius="0.035"/>
      </geometry>
      <material name="black"/>
    </visual>
    <collision>
      <geometry>
        <cylinder length="0.05" radius="0.035"/>
      </geometry>
    </collision>
    <inertial>
      <mass value="0.1"/>
      <inertia ixx="5.1458e-5" iyy="5.1458e-5" izz="6.125e-5" ixy="0" ixz="0" iyz="0"/>
    </inertial>
  </link>

  <joint name="left_wheel_joint" type="continuous">
    <axis xyz="0 0 1"/>
    <parent link="base_link"/>
    <child link="left_wheel"/>
    <origin rpy="-1.5708 0 0" xyz="-0.2825 0.125 -.15"/>
  </joint>

    <link name="lidar_link">
      <visual>
        <geometry>
          <cylinder radius="0.03" length="0.05"/>
        </geometry>
        <material name="grey">
          <color rgba="0.5 0.5 0.5 1"/>
        </material>
      </visual>
    </link>


    <!-- Fixed joint to attach LIDAR to parent -->
    <joint name="lidar_joint" type="fixed">
      <parent link="base_link"/>
      <child link="lidar_link"/>
      <origin xyz="0 0 0.18" rpy="0 0 0"/>
    </joint>

  <!-- plugin for teleop -->
  <gazebo>
    <plugin
        filename="gz-sim-diff-drive-system"
        name="gz::sim::systems::DiffDrive">
        <left_joint>left_wheel_joint</left_joint>
        <right_joint>right_wheel_joint</right_joint>
        <wheel_separation>0.25</wheel_separation>
        <wheel_radius>0.035</wheel_radius>
        <topic>/cmd_vel</topic>
    </plugin>
  </gazebo>

    <!-- LIDAR Link -->
    <gazebo reference="lidar_link">
        <sensor name='gpu_lidar' type='gpu_lidar'>"
          <pose relative_to='lidar_link'>0 0 0 0 0 0</pose>
          <gz_frame_id>lidar_link</gz_frame_id>
          <topic>scan</topic>
          <update_rate>10</update_rate>
          <ray>
              <scan>
                  <horizontal>
                      <samples>640</samples>
                      <resolution>1</resolution>
                      <min_angle>-3.14159</min_angle>
                      <max_angle>3.14159</max_angle>
                       <!-- -0.2617993877991494 15 degree -->
                  </horizontal>
                  <vertical>
                      <samples>1</samples>
                      <resolution>0.01</resolution>
                      <min_angle>0</min_angle>
                      <max_angle>0</max_angle>
                  </vertical>
              </scan>
              <range>
                  <min>0.07</min>
                  <max>10.0</max>
                  <resolution>0.01</resolution>
              </range>
              <noise type="gaussian">
                 <mean>0.0</mean>
                 <stddev>0.05</stddev>
              </noise>
          </ray>
          <always_on>1</always_on>
          <visualize>true</visualize>

          <!-- lidar_plugin -->
          <plugin  filename="gz-sim-sensors-system"  
            name="gz::sim::systems::Sensors"> 
            <render_engine>ogre2</render_engine>
          </plugin>

      </sensor>
    </gazebo>
    

</robot>  
